<?xml version="1.0"?>
<robot name="four_wheel_robot">

  <!-- Base Link -->
  <link name="base_link">
    <inertial>
      <origin xyz="0 0 0.05" rpy="0 0 0"/>
      <mass value="10"/>
      <inertia ixx="0.05" ixy="0" ixz="0" iyy="0.06" iyz="0" izz="0.03"/>
    </inertial>
    <visual>
      <origin xyz="0 0 0.05" rpy="0 0 0"/>
      <geometry>
        <box size="0.4 0.2 0.1"/>
      </geometry>
    </visual>
    <collision>
      <origin xyz="0 0 0.05" rpy="0 0 0"/>
      <geometry>
        <box size="0.4 0.2 0.1"/>
      </geometry>
    </collision>
  </link>

  <!-- Wheel Links -->
  <link name="front_left_wheel">
    <inertial>
      <origin xyz="0 0 0" rpy="0 0 0"/>
      <mass value="1"/>
      <inertia ixx="0.004" ixy="0" ixz="0" iyy="0.004" iyz="0" izz="0.004"/>
    </inertial>
    <visual>
      <origin xyz="0 0 0" rpy="1.5707963 0 0"/>
      <geometry>
        <cylinder radius="0.04" length="0.02"/>
      </geometry>
    </visual>
    <collision>
      <origin xyz="0 0 0" rpy="1.5707963 0 0"/>
      <geometry>
        <cylinder radius="0.04" length="0.02"/>
      </geometry>
    </collision>
  </link>

  <link name="front_right_wheel">
    <inertial>
      <origin xyz="0 0 0" rpy="0 0 0"/>
      <mass value="1"/>
      <inertia ixx="0.004" ixy="0" ixz="0" iyy="0.004" iyz="0" izz="0.004"/>
    </inertial>
    <visual>
      <origin xyz="0 0 0" rpy="1.5707963 0 0"/>
      <geometry>
        <cylinder radius="0.04" length="0.02"/>
      </geometry>
    </visual>
    <collision>
      <origin xyz="0 0 0" rpy="1.5707963 0 0"/>
      <geometry>
        <cylinder radius="0.04" length="0.02"/>
      </geometry>
    </collision>
  </link>

  <link name="rear_left_wheel">
    <inertial>
      <origin xyz="0 0 0" rpy="0 0 0"/>
      <mass value="1"/>
      <inertia ixx="0.004" ixy="0" ixz="0" iyy="0.004" iyz="0" izz="0.004"/>
    </inertial>
    <visual>
      <origin xyz="0 0 0" rpy="1.5707963 0 0"/>
      <geometry>
        <cylinder radius="0.04" length="0.02"/>
      </geometry>
    </visual>
    <collision>
      <origin xyz="0 0 0" rpy="1.5707963 0 0"/>
      <geometry>
        <cylinder radius="0.04" length="0.02"/>
      </geometry>
    </collision>
  </link>

  <link name="rear_right_wheel">
    <inertial>
      <origin xyz="0 0 0" rpy="0 0 0"/>
      <mass value="1"/>
      <inertia ixx="0.004" ixy="0" ixz="0" iyy="0.004" iyz="0" izz="0.004"/>
    </inertial>
    <visual>
      <origin xyz="0 0 0" rpy="1.5707963 0 0"/>
      <geometry>
        <cylinder radius="0.04" length="0.02"/>
      </geometry>
    </visual>
    <collision>
      <origin xyz="0 0 0" rpy="1.5707963 0 0"/>
      <geometry>
        <cylinder radius="0.04" length="0.02"/>
      </geometry>
    </collision>
  </link>

  <!-- Joint Definitions -->
  <joint name="front_left_wheel_joint" type="continuous">
    <origin xyz="0.1 0.1 0" rpy="0 0 0"/>
    <parent link="base_link"/>
    <child link="front_left_wheel"/>
    <axis xyz="0 1 0"/>
  </joint>

  <joint name="front_right_wheel_joint" type="continuous">
    <origin xyz="0.1 -0.1 0" rpy="0 0 0"/>
    <parent link="base_link"/>
    <child link="front_right_wheel"/>
    <axis xyz="0 1 0"/>
  </joint>

  <joint name="rear_left_wheel_joint" type="continuous">
    <origin xyz="-0.1 0.1 0" rpy="0 0 0"/>
    <parent link="base_link"/>
    <child link="rear_left_wheel"/>
    <axis xyz="0 1 0"/>
  </joint>

  <joint name="rear_right_wheel_joint" type="continuous">
    <origin xyz="-0.1 -0.1 0" rpy="0 0 0"/>
    <parent link="base_link"/>
    <child link="rear_right_wheel"/>
    <axis xyz="0 1 0"/>
  </joint>

</robot>
